<?xml version="1.0" ?>
<robot name="pan_tilt_robot">

  <!-- Base -->
  <link name="base_link">
    <inertial>
      <mass value="1.0"/>
      <origin xyz="0 0 0.005"/>
      <inertia ixx="0.001" ixy="0" ixz="0" iyy="0.001" iyz="0" izz="0.001"/>
    </inertial>
    <visual>
      <origin rpy="0 0 -1.5708" xyz="0 0 0"/>
      <geometry>
        <mesh filename="package://pan_tilt_description/urdf/mesh/base.stl"/>

      </geometry>
      <material name="gray">
        <color rgba="0.2 0.2 0.2 1"/>
      </material>
    </visual>
    <collision>
      <origin xyz="0 0 -0.005"/>
      <geometry>
        <box size="0.12 0.12 0.01"/>
      </geometry>
    </collision>
  </link>

  <!-- Yaw -->
  <link name="pan_tilt_yaw_link">
    <inertial>
      <mass value="0.5"/>
      <origin xyz="0 0 0.01"/>
      <inertia ixx="0.0005" ixy="0" ixz="0" iyy="0.0005" iyz="0" izz="0.0005"/>
    </inertial>
    <visual>
      <origin rpy="0 0 -1.5708" xyz="0 0 0"/>
      <geometry>
        <mesh filename="package://pan_tilt_description/urdf/mesh/yaw.stl"/>
      </geometry>
      <material name="gray"/>
    </visual>
    <collision>
      <origin xyz="0 0 0"/>
      <geometry>
        <cylinder radius="0.03" length="0.02"/>
      </geometry>
    </collision>
  </link>

  <joint name="pan_tilt_yaw_joint" type="revolute">
    <origin xyz="0 0 0.023" rpy="0 0 0"/>
    <parent link="base_link"/>
    <child link="pan_tilt_yaw_link"/>
    <axis xyz="0 0 1"/>
    <limit lower="-1.0472" upper="1.0472" velocity="0.5" effort="1.0"/>
  </joint>

  <!-- Pitch -->
  <link name="pan_tilt_pitch_link">
    <inertial>
      <mass value="0.5"/>
      <origin xyz="0 0 0.01"/>
      <inertia ixx="0.0005" ixy="0" ixz="0" iyy="0.0005" iyz="0" izz="0.0005"/>
    </inertial>
    <visual>
      <origin rpy="0 0 -1.5708" xyz="0 0 0"/>
      <geometry>
        <mesh filename="package://pan_tilt_description/urdf/mesh/pitch.stl"/>
      </geometry>
      <material name="gray"/>
    </visual>
    <collision>
      <origin xyz="0 0 0"/>
      <geometry>
        <cylinder radius="0.025" length="0.02"/>
      </geometry>
    </collision>
  </link>

  <joint name="pan_tilt_pitch_joint" type="revolute">
    <origin xyz="0 0 0.062" rpy="0 0 0"/>
    <parent link="pan_tilt_yaw_link"/>
    <child link="pan_tilt_pitch_link"/>
    <axis xyz="0 1 0"/>
    <limit lower="-1.0472" upper="1.0472" velocity="0.5" effort="1.0"/>
  </joint>

  <!-- Cámara falsa estilo Kinect DK -->
  <link name="camera_mount"/>
  <joint name="camera_mount_joint" type="fixed">
    <parent link="pan_tilt_pitch_link"/>
    <child link="camera_mount"/>
    <origin xyz="0 0 0.032" rpy="0 0 0"/>
  </joint>

  <link name="camera_body">
    <inertial>
      <mass value="0.3"/>
      <origin xyz="0 0 0.013"/>
      <inertia ixx="0.0001" iyy="0.0001" izz="0.0001" ixy="0" ixz="0" iyz="0"/>
    </inertial>
    <visual>
      <origin xyz="0 0 0"/>
      <geometry>
        <box size="0.10046 0.10230 0.0260"/>
      </geometry>
      <material name="white">
        <color rgba="0.9 0.9 0.9 1"/>
      </material>
    </visual>
  </link>
  <joint name="mount_to_camera_body" type="fixed">
    <parent link="camera_mount"/>
    <child link="camera_body"/>
    <origin xyz="-0.01485 0.0 0.0130" rpy="0 0 0"/>
  </joint>

  <link name="camera_base">
    <visual>
      <origin xyz="-0.013 0.0 0.0"/>
      <geometry>
        <box size="0.026 0.103 0.039"/>
      </geometry>
      <material name="grey">
        <color rgba="0.6 0.6 0.6 1"/>
      </material>
    </visual>
  </link>
  <joint name="camera_body_to_base" type="fixed">
    <parent link="camera_body"/>
    <child link="camera_base"/>
    <origin xyz="0.07715 0.0 -0.0065" rpy="0 0 0"/>
  </joint>

  <link name="camera_visor">
    <visual>
      <origin xyz="-0.0128 0.0 0.0"/>
      <geometry>
        <box size="0.026 0.101 0.037"/>
      </geometry>
      <material name="black">
        <color rgba="0.0 0.0 0.0 1"/>
      </material>
    </visual>
  </link>
  <joint name="camera_base_to_visor" type="fixed">
    <parent link="camera_base"/>
    <child link="camera_visor"/>
    <origin xyz="0 0 0" rpy="0 0 0"/>
  </joint>

</robot>